<?xml version="1.0"?>
<robot name="doosan_a0509" xmlns:xacro="http://ros.org/wiki/xacro">

  <link name="base" />
  
  <joint name="fixed" type="fixed">
    <parent link="base" />
    <child link="base_link" />
  </joint>

  <link name="base_link">
    <inertial>
	    <mass value="3.722"/>
	    <origin xyz="-1.2e-05 -6e-05 0.050723"/>
      <inertia ixx="0.011" ixy="-7.19e-06" ixz="-1.94e-06" iyy="0.011" iyz="4.9e-06" izz="0.014"/>
    </inertial>
  	<visual>
      <origin rpy="0 0 0" xyz="0 0 0" />
      <geometry>
          <mesh filename="package://dsr_a0509_description/meshes/A0509_0_0.dae" scale="0.001 0.001 0.001"/>
      </geometry>
    </visual>
  </link>
  
  <joint name="shoulder_joint" type="revolute">
    <parent link="base_link" />
    <child link="shoulder_link" />
    <origin xyz="0 0 0.1525" rpy="0 0 0" />
    <axis xyz="0 0 1" />
    <limit effort="30" lower="-2.617" upper="2.617" velocity="1.571"/>
  </joint>
  
  <link name="shoulder_link">
    <inertial>
	  <mass value="7.446"/>
	  <origin xyz="7e-05 0.044281 0.143327"/>
      <inertia ixx="0.039" ixy="2.1e-05" ixz="-3.61e-05" iyy="0.023" iyz="-0.003" izz="0.039"/>
    </inertial>
    <visual>
      <geometry>
        <mesh filename="package://dsr_a0509_description/meshes/A0509_1_0.dae" scale="0.001 0.001 0.001" />
      </geometry>
      <origin rpy="0 0 0" xyz="0 0 0" />
   </visual>
    <visual>
      <geometry>
        <mesh filename="package://dsr_a0509_description/meshes/A0509_1_1.dae" scale="0.001 0.001 0.001" />
      </geometry>
      <origin rpy="0 0 0" xyz="0 0 0" />
    </visual>
    <visual>
      <geometry>
        <mesh filename="package://dsr_a0509_description/meshes/A0509_1_2.dae" scale="0.001 0.001 0.001" />
      </geometry>
      <origin rpy="0 0 0" xyz="0 0 0" />
    </visual>
  </link>

  <joint name="elbow_joint" type="revolute">
    <parent link="shoulder_link" />
    <child link="elbow_link" />
    <origin rpy="0 -1.571 -1.571" xyz="0 0 0"/>
    <axis xyz="0 0 1" />
    <limit effort="30" lower="-2.617" upper="2.617" velocity="1.571"/>
  </joint>
  
  <link name="elbow_link">
    <inertial>
	    <mass value="10.569"/>
	    <origin xyz="-1.6e-05 0.189372 0.418558"/>
      <inertia ixx="0.820" ixy="1.19e-05" ixz="-0.000263" iyy="0.82" iyz="-0.008" izz="0.031"/>
    </inertial>
  	<visual>
      <geometry>
        <mesh filename="package://dsr_a0509_description/meshes/A0509_2_0.dae" scale="0.001 0.001 0.001" />
      </geometry>
      <origin rpy="0 0 0" xyz="0 0 0" />
    </visual>
    <visual>
      <geometry>
        <mesh filename="package://dsr_a0509_description/meshes/A0509_2_1.dae" scale="0.001 0.001 0.001" />
      </geometry>
      <origin rpy="0 0 0" xyz="0 0 0" />
    </visual>
    <visual>
      <geometry>
        <mesh filename="package://dsr_a0509_description/meshes/A0509_2_2.dae" scale="0.001 0.001 0.001" />
      </geometry>
      <origin rpy="0 0 0" xyz="0 0 0" />
    </visual>
  </link>

  <joint name="wrist_pitch_joint" type="revolute">
    <parent link="elbow_link" />
    <child link="wrist_pitch_link" />
    <origin rpy="0 0 1.571" xyz="0.409 0 0"/>
    <axis xyz="0 0 1" />
    <limit effort="30" lower="-2.617" upper="2.617" velocity="1.571"/>
  </joint>
  
  <link name="wrist_pitch_link">
    <inertial>
	    <mass value="3.614"/>
	    <origin xyz="6e-06 0.07917 0.781807"/>
      <inertia ixx="0.012" ixy="-4.38e-06" ixz="-1.2e-06" iyy="0.008" iyz="0.002" izz="0.011"/>
    </inertial>
    <visual>
      <geometry>
        <mesh filename="package://dsr_a0509_description/meshes/A0509_3_0.dae" scale="0.001 0.001 0.001" />
      </geometry>
      <origin rpy="0 0 0" xyz="0 0 0" />
    </visual>
    <visual>
      <geometry>
        <mesh filename="package://dsr_a0509_description/meshes/A0509_3_1.dae" scale="0.001 0.001 0.001" />
      </geometry>
      <origin rpy="0 0 0" xyz="0 0 0" />
    </visual>
  </link>

  <joint name="wrist_roll_joint" type="revolute">
    <parent link="wrist_pitch_link" />
    <child link="wrist_roll_link" />
    <origin rpy="1.571 0 0" xyz="0 -0.367 0"/>
    <axis xyz="0 0 1" />
    <limit effort="30" lower="-2.617" upper="2.617" velocity="1.571"/>
  </joint>
  
  <link name="wrist_roll_link">
    <inertial>
	    <mass value="3.785"/>
	    <origin xyz="-2.1e-05 0.12337 1.148"/>
      <inertia ixx="0.177" ixy="-2.34e-06" ixz="-4.92e-06" iyy="0.161" iyz="-0.05" izz="0.022"/>
    </inertial>
  	<visual>
      <geometry>
        <mesh filename="package://dsr_a0509_description/meshes/A0509_4_0.dae" scale="0.001 0.001 0.001" />
      </geometry>
      <origin rpy="0 0 0" xyz="0 0 0" />
    </visual>
    <visual>
      <geometry>
        <mesh filename="package://dsr_a0509_description/meshes/A0509_4_1.dae" scale="0.001 0.001 0.001" />
      </geometry>
      <origin rpy="0 0 0" xyz="0 0 0" />
    </visual>
  </link>

  <joint name="wrist_yaw_joint" type="revolute">
    <parent link="wrist_roll_link" />
    <child link="wrist_yaw_link" />
    <origin rpy="-1.571 0 0" xyz="0 0 0"/>
    <axis xyz="0 0 1" />
    <limit effort="30" lower="-2.617" upper="2.617" velocity="1.571"/>
  </joint>
  
  <link name="wrist_yaw_link">
    <inertial>
	    <mass value="2.598"/>
	    <origin xyz="-1.7e-05 0.06662 1.33103"/>
      <inertia ixx="0.007" ixy="-4.93e-06" ixz="-5.57e-06" iyy="0.004" iyz="-6.64e-05" izz="0.007"/>
    </inertial>
  	<visual>
      <geometry>
        <mesh filename="package://dsr_a0509_description/meshes/A0509_5_0.dae" scale="0.001 0.001 0.001" />
      </geometry>
      <origin rpy="0 0 0" xyz="0 0 0" />
    </visual>
    <visual>
      <geometry>
        <mesh filename="package://dsr_a0509_description/meshes/A0509_5_1.dae" scale="0.001 0.001 0.001" />
      </geometry>
      <origin rpy="0 0 0" xyz="0 0 0" />
    </visual>
  </link>

  <joint name="end_effector_joint" type="revolute">
    <parent link="wrist_yaw_link" />
    <child link="end_effector_link" />
    <origin rpy="1.571 0 0" xyz="0 -0.124 0"/>
    <axis xyz="0 0 1" />
    <limit effort="30" lower="-2.617" upper="2.617" velocity="1.571"/>
  </joint>
  
  <link name="end_effector_link">
    <inertial>
	    <mass value="1.128"/>
	    <origin xyz="-0.000174 0.034708 1.40022"/>
      <inertia ixx="0.001" ixy="-2.79e-06" ixz="5.78e-06" iyy="0.001" iyz="-6.67e-06" izz="0.001"/>
    </inertial>
  	<visual>
      <geometry>
        <mesh filename="package://dsr_a0509_description/meshes/A0509_6_0.dae" scale="0.001 0.001 0.001" />
      </geometry>
      <origin rpy="0 0 0" xyz="0 0 0" />
    </visual>
  </link>

</robot>
