<sdf version='1.7'>
  <model name='doosan_a0509'>
    <link name='base'>
      <inertial>
        <pose>-1.2e-05 -6e-05 0.050723 0 -0 0</pose>
        <mass>3.722</mass>
        <inertia>
          <ixx>0.011</ixx>
          <ixy>-7.19e-06</ixy>
          <ixz>-1.94e-06</ixz>
          <iyy>0.011</iyy>
          <iyz>4.9e-06</iyz>
          <izz>0.014</izz>
        </inertia>
      </inertial>
      <visual name='base_link_visual'>
        <pose>0 0 0 0 -0 0</pose>
        <geometry>
          <mesh>
            <scale>0.001 0.001 0.001</scale>
            <uri>model://robot_arm/meshes/A0509_0_0.dae</uri>
          </mesh>
        </geometry>
      </visual>
    </link>
    <joint name='shoulder_joint' type='revolute'>
      <pose relative_to='base'>0 0 0.1525 0 -0 0</pose>
      <parent>base</parent>
      <child>shoulder_link</child>
      <axis>
        <xyz>0 0 1</xyz>
        <limit>
          <lower>-2.617</lower>
          <upper>2.617</upper>
          <effort>30</effort>
          <velocity>1.571</velocity>
        </limit>
        <dynamics>
          <spring_reference>0</spring_reference>
          <spring_stiffness>0</spring_stiffness>
        </dynamics>
      </axis>
    </joint>
    <link name='shoulder_link'>
      <pose relative_to='shoulder_joint'>0 0 0 0 -0 0</pose>
      <inertial>
        <pose>7e-05 0.044281 0.143327 0 -0 0</pose>
        <mass>7.446</mass>
        <inertia>
          <ixx>0.039</ixx>
          <ixy>2.1e-05</ixy>
          <ixz>-3.61e-05</ixz>
          <iyy>0.023</iyy>
          <iyz>-0.003</iyz>
          <izz>0.039</izz>
        </inertia>
      </inertial>
      <visual name='shoulder_link_visual'>
        <pose>0 0 0 0 -0 0</pose>
        <geometry>
          <mesh>
            <scale>0.001 0.001 0.001</scale>
            <uri>model://robot_arm/meshes/A0509_1_0.dae</uri>
          </mesh>
        </geometry>
      </visual>
      <visual name='shoulder_link_visual_1'>
        <pose>0 0 0 0 -0 0</pose>
        <geometry>
          <mesh>
            <scale>0.001 0.001 0.001</scale>
            <uri>model://robot_arm/meshes/A0509_1_1.dae</uri>
          </mesh>
        </geometry>
      </visual>
      <visual name='shoulder_link_visual_2'>
        <pose>0 0 0 0 -0 0</pose>
        <geometry>
          <mesh>
            <scale>0.001 0.001 0.001</scale>
            <uri>model://robot_arm/meshes/A0509_1_2.dae</uri>
          </mesh>
        </geometry>
      </visual>
    </link>
    <joint name='elbow_joint' type='revolute'>
      <pose relative_to='shoulder_link'>0 0 0 3.14159 -1.57059 1.57059</pose>
      <parent>shoulder_link</parent>
      <child>elbow_link</child>
      <axis>
        <xyz>0 0 1</xyz>
        <limit>
          <lower>-2.617</lower>
          <upper>2.617</upper>
          <effort>30</effort>
          <velocity>1.571</velocity>
        </limit>
        <dynamics>
          <spring_reference>0</spring_reference>
          <spring_stiffness>0</spring_stiffness>
        </dynamics>
      </axis>
    </joint>
    <link name='elbow_link'>
      <pose relative_to='elbow_joint'>0 0 0 0 -0 0</pose>
      <inertial>
        <pose>-1.6e-05 0.189372 0.418558 0 -0 0</pose>
        <mass>10.569</mass>
        <inertia>
          <ixx>0.82</ixx>
          <ixy>1.19e-05</ixy>
          <ixz>-0.000263</ixz>
          <iyy>0.82</iyy>
          <iyz>-0.008</iyz>
          <izz>0.031</izz>
        </inertia>
      </inertial>
      <visual name='elbow_link_visual'>
        <pose>0 0 0 0 -0 0</pose>
        <geometry>
          <mesh>
            <scale>0.001 0.001 0.001</scale>
            <uri>model://robot_arm/meshes/A0509_2_0.dae</uri>
          </mesh>
        </geometry>
      </visual>
      <visual name='elbow_link_visual_1'>
        <pose>0 0 0 0 -0 0</pose>
        <geometry>
          <mesh>
            <scale>0.001 0.001 0.001</scale>
            <uri>model://robot_arm/meshes/A0509_2_1.dae</uri>
          </mesh>
        </geometry>
      </visual>
      <visual name='elbow_link_visual_2'>
        <pose>0 0 0 0 -0 0</pose>
        <geometry>
          <mesh>
            <scale>0.001 0.001 0.001</scale>
            <uri>model://robot_arm/meshes/A0509_2_2.dae</uri>
          </mesh>
        </geometry>
      </visual>
    </link>
    <joint name='wrist_pitch_joint' type='revolute'>
      <pose relative_to='elbow_link'>0.409 0 0 0 -0 1.571</pose>
      <parent>elbow_link</parent>
      <child>wrist_pitch_link</child>
      <axis>
        <xyz>0 0 1</xyz>
        <limit>
          <lower>-2.617</lower>
          <upper>2.617</upper>
          <effort>30</effort>
          <velocity>1.571</velocity>
        </limit>
        <dynamics>
          <spring_reference>0</spring_reference>
          <spring_stiffness>0</spring_stiffness>
        </dynamics>
      </axis>
    </joint>
    <link name='wrist_pitch_link'>
      <pose relative_to='wrist_pitch_joint'>0 0 0 0 -0 0</pose>
      <inertial>
        <pose>6e-06 0.07917 0.781807 0 -0 0</pose>
        <mass>3.614</mass>
        <inertia>
          <ixx>0.012</ixx>
          <ixy>-4.38e-06</ixy>
          <ixz>-1.2e-06</ixz>
          <iyy>0.008</iyy>
          <iyz>0.002</iyz>
          <izz>0.011</izz>
        </inertia>
      </inertial>
      <visual name='wrist_pitch_link_visual'>
        <pose>0 0 0 0 -0 0</pose>
        <geometry>
          <mesh>
            <scale>0.001 0.001 0.001</scale>
            <uri>model://robot_arm/meshes/A0509_3_0.dae</uri>
          </mesh>
        </geometry>
      </visual>
      <visual name='wrist_pitch_link_visual_1'>
        <pose>0 0 0 0 -0 0</pose>
        <geometry>
          <mesh>
            <scale>0.001 0.001 0.001</scale>
            <uri>model://robot_arm/meshes/A0509_3_1.dae</uri>
          </mesh>
        </geometry>
      </visual>
    </link>
    <joint name='wrist_roll_joint' type='revolute'>
      <pose relative_to='wrist_pitch_link'>0 -0.367 0 1.571 -0 0</pose>
      <parent>wrist_pitch_link</parent>
      <child>wrist_roll_link</child>
      <axis>
        <xyz>0 0 1</xyz>
        <limit>
          <lower>-2.617</lower>
          <upper>2.617</upper>
          <effort>30</effort>
          <velocity>1.571</velocity>
        </limit>
        <dynamics>
          <spring_reference>0</spring_reference>
          <spring_stiffness>0</spring_stiffness>
        </dynamics>
      </axis>
    </joint>
    <link name='wrist_roll_link'>
      <pose relative_to='wrist_roll_joint'>0 0 0 0 -0 0</pose>
      <inertial>
        <pose>-2.1e-05 0.12337 1.148 0 -0 0</pose>
        <mass>3.785</mass>
        <inertia>
          <ixx>0.177</ixx>
          <ixy>-2.34e-06</ixy>
          <ixz>-4.92e-06</ixz>
          <iyy>0.161</iyy>
          <iyz>-0.05</iyz>
          <izz>0.022</izz>
        </inertia>
      </inertial>
      <visual name='wrist_roll_link_visual'>
        <pose>0 0 0 0 -0 0</pose>
        <geometry>
          <mesh>
            <scale>0.001 0.001 0.001</scale>
            <uri>model://robot_arm/meshes/A0509_4_0.dae</uri>
          </mesh>
        </geometry>
      </visual>
      <visual name='wrist_roll_link_visual_1'>
        <pose>0 0 0 0 -0 0</pose>
        <geometry>
          <mesh>
            <scale>0.001 0.001 0.001</scale>
            <uri>model://robot_arm/meshes/A0509_4_1.dae</uri>
          </mesh>
        </geometry>
      </visual>
    </link>
    <joint name='wrist_yaw_joint' type='revolute'>
      <pose relative_to='wrist_roll_link'>0 0 0 -1.571 0 0</pose>
      <parent>wrist_roll_link</parent>
      <child>wrist_yaw_link</child>
      <axis>
        <xyz>0 0 1</xyz>
        <limit>
          <lower>-2.617</lower>
          <upper>2.617</upper>
          <effort>30</effort>
          <velocity>1.571</velocity>
        </limit>
        <dynamics>
          <spring_reference>0</spring_reference>
          <spring_stiffness>0</spring_stiffness>
        </dynamics>
      </axis>
    </joint>
    <link name='wrist_yaw_link'>
      <pose relative_to='wrist_yaw_joint'>0 0 0 0 -0 0</pose>
      <inertial>
        <pose>-1.7e-05 0.06662 1.33103 0 -0 0</pose>
        <mass>2.598</mass>
        <inertia>
          <ixx>0.007</ixx>
          <ixy>-4.93e-06</ixy>
          <ixz>-5.57e-06</ixz>
          <iyy>0.004</iyy>
          <iyz>-6.64e-05</iyz>
          <izz>0.007</izz>
        </inertia>
      </inertial>
      <visual name='wrist_yaw_link_visual'>
        <pose>0 0 0 0 -0 0</pose>
        <geometry>
          <mesh>
            <scale>0.001 0.001 0.001</scale>
            <uri>model://robot_arm/meshes/A0509_5_0.dae</uri>
          </mesh>
        </geometry>
      </visual>
      <visual name='wrist_yaw_link_visual_1'>
        <pose>0 0 0 0 -0 0</pose>
        <geometry>
          <mesh>
            <scale>0.001 0.001 0.001</scale>
            <uri>model://robot_arm/meshes/A0509_5_1.dae</uri>
          </mesh>
        </geometry>
      </visual>
    </link>
    <joint name='end_effector_joint' type='revolute'>
      <pose relative_to='wrist_yaw_link'>0 -0.124 0 1.571 -0 0</pose>
      <parent>wrist_yaw_link</parent>
      <child>end_effector_link</child>
      <axis>
        <xyz>0 0 1</xyz>
        <limit>
          <lower>-2.617</lower>
          <upper>2.617</upper>
          <effort>30</effort>
          <velocity>1.571</velocity>
        </limit>
        <dynamics>
          <spring_reference>0</spring_reference>
          <spring_stiffness>0</spring_stiffness>
        </dynamics>
      </axis>
    </joint>
    <link name='end_effector_link'>
      <pose relative_to='end_effector_joint'>0 0 0 0 -0 0</pose>
      <inertial>
        <pose>-0.000174 0.034708 1.40022 0 -0 0</pose>
        <mass>1.128</mass>
        <inertia>
          <ixx>0.001</ixx>
          <ixy>-2.79e-06</ixy>
          <ixz>5.78e-06</ixz>
          <iyy>0.001</iyy>
          <iyz>-6.67e-06</iyz>
          <izz>0.001</izz>
        </inertia>
      </inertial>
      <visual name='end_effector_link_visual'>
        <pose>0 0 0 0 -0 0</pose>
        <geometry>
          <mesh>
            <scale>0.001 0.001 0.001</scale>
            <uri>model://robot_arm/meshes/A0509_6_0.dae</uri>
          </mesh>
        </geometry>
      </visual>
    </link>
  </model>
</sdf>
